Workbook

Sheet INITIAL
A1: URBAN GAZ
A3: PROJECT NAME: SIMCO
A4: INITIAL DATASET
A6: SL | B6: FLAT NUMBER | C6: METER READING [m3] | D6: NAME OF OWNER | E6: CONTACT | F6: REMARKS
A8: 1 | B8: 2A1 | C8: 0.112
A9: 2 | B9: 3A1 | C9: 0.177
A10: 3 | B10: 4A1 | C10: 0.158
A11: 4 | B11: 5A1 | C11: 0.151 | D11: MR. MEHEDI HASAN | E11: (+880)1717083525
A12: 5 | B12: 7A1 | C12: 0.128
A13: 6 | B13: 8A1 | C13: 0.141
A14: 7 | B14: 9A1 | C14: 0.151
A15: 8 | B15: 10A1 | C15: 0.159
A16: 9 | B16: 11A1 | C16: 0.171
A17: 10 | B17: 12A1 | C17: 0.525
A18: 11 | B18: 2B1 | C18: 0.411
A19: 12 | B19: 3B1 | C19: 0.378
A20: 13 | B20: 4B1 | C20: 0.612
A21: 14 | B21: 5B1 | C21: 0.337
A22: 15 | B22: 6B1 | C22: 0.161 | D22: MRS. SHORNA RAY | E22: (+880)1729575057
A23: 16 | B23: 7B1 | C23: 0.187 | D23: MR. RAKIB | E23: (+880)1670226186
A24: 17 | B24: 8B1 | C24: 0.221 | F24: STARTED JUNE
A25: 18 | B25: 9B1 | C25: 0.376 | F25: STARTED JUNE
A26: 19 | B26: 10B1 | C26: 0.336
A27: 20 | B27: 11B1 | C27: 0.262
A28: 21 | B28: 2C1 | C28: 0.646 | D28: MR. HABIBUR RAHMAN
A29: 22 | B29: 3C1 | C29: 0.416
A30: 23 | B30: 4C1 | C30: 0.171
A31: 24 | B31: 5C1 | C31: 0.546
A32: 25 | B32: 6C1 | C32: 0.156 | D32: MR. SHAMIM AKTER | E32: (+880)1716096841
A33: 26 | B33: 7C1 | C33: 0.187 | D33: MD. SHAHRIAR KAMAL | E33: (+880)1715977377
A34: 27 | B34: 8C1 | C34: 0.178 | F34: STARTED JUNE
A35: 28 | B35: 9C1 | C35: 0.166
A36: 29 | B36: 10C1 | C36: 0.166
A37: 30 | B37: 11C1 | C37: 0.539
A38: 31 | B38: 12C1 | C38: 0.168
A39: 32 | B39: 2A4 | C39: 0.387
A40: 33 | B40: 3A4 | C40: 0.444
A41: 34 | B41: 4A4 | C41: 0.638 | D41: MD. NIZAM UDDIN
A42: 35 | B42: 5A4 | C42: 0.407
A43: 36 | B43: 6A4 | C43: 0.339
...

Sheet R, C & BILL
A1: URBAN GAZ @ JOLSHIRI ABASHON
A3: CONSUMPTION DATA SHEET - SURZO DREAM HOUSE
A6: SL NO | B6: FLAT NUMBER | C6: INITIAL METER READING
E7: JANUARY - 2026 | J7: FEBRUARY - 2026 | O7: MARCH - 2026 | T7: APRIL - 2026 | Y7: MAY - 2026 | AD7: JUNE - 2026 | AI7: JULY - 2026 | AN7: AUGUST - 2026 | AS7: SEPTEMBER - 2026 | AX7: OCTOBER - 2026 | BC7: NOVEMBER - 2026 | BH7: DECEMBER - 2026
E8: UNIT PRICE @ 241.60 TAKA/M3 | J8: UNIT PRICE @ 250.95 TAKA/M3 | O8: UNIT PRICE @ 248.06 TAKA/M3 | T8: UNIT PRICE @ 358.90 TAKA/M3 | Y8: UNIT PRICE @ XXX.XX TAKA/M3 | AD8: UNIT PRICE @ XXX.XX TAKA/M3 | AI8: UNIT PRICE @ 252.28 TAKA/M3 | AN8: UNIT PRICE @ 235.60 TAKA/M3 | AS8: UNIT PRICE @ 235.05 TAKA/M3 | AX8: UNIT PRICE @ 229.55 TAKA/M3 | BC8: UNIT PRICE @ 232 TAKA/M3 | BH8: UNIT PRICE @ 231.80 TAKA/M3
E9: READEING | F9: CONSUMPTION | G9: GAS [BDT] | H9: M F [BDT] | I9: TOTAL BILL [BDT] | J9: READEING | K9: CONSUMPTION | L9: GAS [BDT] | M9: M F [BDT] | N9: TOTAL BILL [BDT] | O9: READEING | P9: CONSUMPTION | Q9: GAS [BDT] | R9: M F [BDT] | S9: TOTAL BILL [BDT] | T9: READEING | U9: CONSUMPTION | V9: GAS [BDT] | W9: M F [BDT] | X9: TOTAL BILL [BDT] | Y9: READEING | Z9: CONSUMPTION | AA9: GAS [BDT] | AB9: M F [BDT] | AC9: TOTAL BILL [BDT] | AD9: READEING | AE9: CONSUMPTION | AF9: GAS [BDT] | AG9: M F [BDT] | AH9: TOTAL BILL [BDT] | AI9: READEING | AJ9: CONSUMPTION | AK9: GAS [BDT] | AL9: M F [BDT] | AM9: TOTAL BILL [BDT] | AO9: CONSUMPTION | AP9: GAS [BDT] | AQ9: M F [BDT] | AR9: TOTAL BILL [BDT] | AS9: READEING | AT9: CONSUMPTION | AU9: GAS [BDT] | AV9: M F [BDT] | AW9: TOTAL BILL [BDT] | AX9: READEING | AY9: CONSUMPTION | AZ9: GAS [BDT] | BA9: M F [BDT] | BB9: TOTAL BILL [BDT] | BC9: READEING | BD9: CONSUMPTION | BE9: GAS [BDT] | BF9: M F [BDT] | BG9: TOTAL BILL [BDT] | BH9: READEING | BI9: CONSUMPTION | BJ9: GAS [BDT] | BK9: M F [BDT] | BL9: TOTAL BILL [BDT]
A10: 1 | B10: 2A | D10: 4.93 | G10: =IF(F10>0,F10*241.6,"0.00") -> 0.00 | H10: =(G10*6%) -> 0 | I10: =G10+H10 -> 0 | J10: 4.93 | K10: =J10-E10 -> 4.93 | L10: =IF(K10>0,K10*250.95,"0.00") -> 1237.1835 | M10: =(L10*6%) -> 74.23101 | N10: =(L10+M10) -> 1311.4145 | O10: 7.175 | P10: =O10-J10 -> 2.245 | Q10: =IF(P10>0,P10*248.06,"0.00") -> 556.8947 | R10: =(Q10*6%) -> 33.413682 | S10: =(Q10+R10) -> 590.30838 | U10: =T10-O10 -> -7.175 | V10: =IF(U10>0,U10*358.9,"0.00") -> 0.00 | W10: =V10*6% -> 0 | X10: =V10+W10 -> 0 | Z10: =Y10-T10 -> 0 | AA10: =IF(Z10>0,Z10*296, "0.00") -> 0.00 | AB10: =AA10*6% -> 0 | AC10: =(AA10+AB10) -> 0 | AE10: =AD10-Y10 -> 0 | AF10: =IF(AE10>0,AE10*296, "0.00") -> 0.00 | AG10: =AF10*6% -> 0 | AH10: =(AF10+AG10) -> 0 | AJ10: =AI10-AD10 -> 0 | AK10: =IF(AJ10>0,AJ10*252.28, "0.00") -> 0.00 | AL10: =AK10*0.06 -> 0 | AM10: =(AK10+AL10) -> 0 | AO10: =(AN10-AI10) -> 0 | AP10: =IF(AO10>0,AO10*235.6, "0.00") -> 0.00 | AQ10: =(AP10*6%) -> 0 | AR10: =(AP10+AQ10) -> 0 | AT10: =(AS10-AN10) -> 0 | AU10: =IF(AT10>0,AT10*235.05, "0.00") -> 0.00 | AV10: =(AU10*6%) -> 0 | AW10: =(AU10+AV10) -> 0 | AZ10: =IF(AY10>0,AY10*229.55, "0.00") -> 0.00 | BA10: =(AZ10*6%) -> 0 | BB10: =(AZ10+BA10) -> 0 | BC10: 2.56 | BD10: =BC10-AX10 -> 2.56 | BE10: =IF(BD10>0,BD10*232,"0.00") -> 593.92 | BF10: =BE10*6% -> 35.6352 | BG10: =BE10+BF10 -> 629.5552 | BI10: =BH10-BC10 -> -2.56 | BJ10: =IF(BI10>0,BI10*231.8,"0.00") -> 0.00 | BK10: =BJ10*6% -> 0 | BL10: =BJ10+BK10 -> 0
A11: 2 | B11: 3A | D11: 127.1 | E11: 137.98 | F11: =E11-D11 -> 10.88 | G11: =IF(F11>0,F11*241.6,"0.00") -> 2628.608 | H11: =(G11*6%) -> 157.71648 | I11: =G11+H11 -> 2786.3245 | J11: 149.18 | K11: =J11-E11 -> 11.2 | L11: =IF(K11>0,K11*250.95,"0.00") -> 2810.64 | M11: =(L11*6%) -> 168.6384 | N11: =(L11+M11) -> 2979.2784 | O11: 157.28 | P11: =O11-J11 -> 8.1 | Q11: =IF(P11>0,P11*248.06,"0.00") -> 2009.286 | R11: =(Q11*6%) -> 120.55716 | S11: =(Q11+R11) -> 2129.8432 | T11: 168.828 | U11: =T11-O11 -> 11.548 | V11: =IF(U11>0,U11*358.9,"0.00") -> 4144.5772 | W11: =V11*6% -> 248.67463 | X11: =V11+W11 -> 4393.2518 | Z11: =Y11-T11 -> -168.828 | AA11: =IF(Z11>0,Z11*296, "0.00") -> 0.00 | AB11: =AA11*6% -> 0 | AC11: =(AA11+AB11) -> 0 | AE11: =AD11-Y11 -> 0 | AF11: =IF(AE11>0,AE11*296, "0.00") -> 0.00 | AG11: =AF11*6% -> 0 | AH11: =(AF11+AG11) -> 0 | AJ11: =AI11-AD11 -> 0 | AK11: =IF(AJ11>0,AJ11*252.28, "0.00") -> 0.00 | AL11: =AK11*0.06 -> 0 | AM11: =(AK11+AL11) -> 0 | AO11: =(AN11-AI11) -> 0 | AP11: =IF(AO11>0,AO11*235.6, "0.00") -> 0.00 | AQ11: =(AP11*6%) -> 0 | AR11: =(AP11+AQ11) -> 0 | AT11: =(AS11-AN11) -> 0 | AU11: =IF(AT11>0,AT11*235.05, "0.00") -> 0.00 | AV11: =(AU11*6%) -> 0 | AW11: =(AU11+AV11) -> 0 | AX11: 96.98 | AZ11: =IF(AY11>0,AY11*229.55, "0.00") -> 0.00 | BA11: =(AZ11*6%) -> 0 | BB11: =(AZ11+BA11) -> 0 | BC11: 118.53 | BD11: =BC11-AX11 -> 21.55 | BE11: =IF(BD11>0,BD11*232,"0.00") -> 4999.6 | BF11: =BE11*6% -> 299.976 | BG11: =BE11+BF11 -> 5299.576 | BI11: =BH11-BC11 -> -118.53 | BJ11: =IF(BI11>0,BI11*231.8,"0.00") -> 0.00 | BK11: =BJ11*6% -> 0 | BL11: =BJ11+BK11 -> 0
A12: 3 | B12: 4A | D12: 40.2 | E12: 43.933 | F12: =E12-D12 -> 3.733 | G12: =IF(F12>0,F12*241.6,"0.00") -> 901.8928 | H12: =(G12*6%) -> 54.113568 | I12: =G12+H12 -> 956.00637 | J12: 46.88 | K12: =J12-E12 -> 2.947 | L12: =IF(K12>0,K12*250.95,"0.00") -> 739.54965 | M12: =(L12*6%) -> 44.372979 | N12: =(L12+M12) -> 783.92263 | O12: 52.057 | P12: =O12-J12 -> 5.177 | Q12: =IF(P12>0,P12*248.06,"0.00") -> 1284.2066 | R12: =(Q12*6%) -> 77.052397 | S12: =(Q12+R12) -> 1361.259 | T12: 54.798 | U12: =T12-O12 -> 2.741 | V12: =IF(U12>0,U12*358.9,"0.00") -> 983.7449 | W12: =V12*6% -> 59.024694 | X12: =V12+W12 -> 1042.7696 | Z12: =Y12-T12 -> -54.798 | AA12: =IF(Z12>0,Z12*296, "0.00") -> 0.00 | AB12: =AA12*6% -> 0 | AC12: =(AA12+AB12) -> 0 | AE12: =AD12-Y12 -> 0 | AF12: =IF(AE12>0,AE12*296, "0.00") -> 0.00 | AG12: =AF12*6% -> 0 | AH12: =(AF12+AG12) -> 0 | AJ12: =AI12-AD12 -> 0 | AK12: =IF(AJ12>0,AJ12*252.28, "0.00") -> 0.00 | AL12: =AK12*0.06 -> 0 | AM12: =(AK12+AL12) -> 0 | AO12: =(AN12-AI12) -> 0 | AP12: =IF(AO12>0,AO12*235.6, "0.00") -> 0.00 | AQ12: =(AP12*6%) -> 0 | AR12: =(AP12+AQ12) -> 0 | AT12: =(AS12-AN12) -> 0 | AU12: =IF(AT12>0,AT12*235.05, "0.00") -> 0.00 | AV12: =(AU12*6%) -> 0 | AW12: =(AU12+AV12) -> 0 | AX12: 30.62 | AZ12: =IF(AY12>0,AY12*229.55, "0.00") -> 0.00 | BA12: =(AZ12*6%) -> 0 | BB12: =(AZ12+BA12) -> 0 | BC12: 37.33 | BD12: =BC12-AX12 -> 6.71 | BE12: =IF(BD12>0,BD12*232,"0.00") -> 1556.72 | BF12: =BE12*6% -> 93.4032 | BG12: =BE12+BF12 -> 1650.1232 | BI12: =BH12-BC12 -> -37.33 | BJ12: =IF(BI12>0,BI12*231.8,"0.00") -> 0.00 | BK12: =BJ12*6% -> 0 | BL12: =BJ12+BK12 -> 0
A13: 4 | B13: 5A | D13: 0.127 | E13: 0.127 | G13: =IF(F13>0,F13*241.6,"0.00") -> 0.00 | H13: =(G13*6%) -> 0 | I13: =G13+H13 -> 0 | J13: 0.742 | K13: =J13-E13 -> 0.615 | L13: =IF(K13>0,K13*250.95,"0.00") -> 154.33425 | M13: =(L13*6%) -> 9.260055 | N13: =(L13+M13) -> 163.5943 | O13: 2.634 | P13: =O13-J13 -> 1.892 | Q13: =IF(P13>0,P13*248.06,"0.00") -> 469.32952 | R13: =(Q13*6%) -> 28.159771 | S13: =(Q13+R13) -> 497.48929 | U13: =T13-O13 -> -2.634 | V13: =IF(U13>0,U13*358.9,"0.00") -> 0.00 | W13: =V13*6% -> 0 | X13: =V13+W13 -> 0 | Z13: =Y13-T13 -> 0 | AA13: =IF(Z13>0,Z13*296, "0.00") -> 0.00 | AB13: =AA13*6% -> 0 | AC13: =(AA13+AB13) -> 0 | AE13: =AD13-Y13 -> 0 | AF13: =IF(AE13>0,AE13*296, "0.00") -> 0.00 | AG13: =AF13*6% -> 0 | AH13: =(AF13+AG13) -> 0 | AJ13: =AI13-AD13 -> 0 | AK13: =IF(AJ13>0,AJ13*252.28, "0.00") -> 0.00 | AL13: =AK13*0.06 -> 0 | AM13: =(AK13+AL13) -> 0 | AO13: =(AN13-AI13) -> 0 | AP13: =IF(AO13>0,AO13*235.6, "0.00") -> 0.00 | AQ13: =(AP13*6%) -> 0 | AR13: =(AP13+AQ13) -> 0 | AT13: =(AS13-AN13) -> 0 | AU13: =IF(AT13>0,AT13*235.05, "0.00") -> 0.00 | AV13: =(AU13*6%) -> 0 | AW13: =(AU13+AV13) -> 0 | AZ13: =IF(AY13>0,AY13*229.55, "0.00") -> 0.00 | BA13: =(AZ13*6%) -> 0 | BB13: =(AZ13+BA13) -> 0 | BD13: =BC13-AX13 -> 0 | BE13: =IF(BD13>0,BD13*232,"0.00") -> 0.00 | BF13: =BE13*6% -> 0 | BG13: =BE13+BF13 -> 0 | BI13: =BH13-BC13 -> 0 | BJ13: =IF(BI13>0,BI13*231.8,"0.00") -> 0.00 | BK13: =BJ13*6% -> 0 | BL13: =BJ13+BK13 -> 0
A14: 5 | B14: 6A | D14: 0.328 | G14: =IF(F14>0,F14*241.6,"0.00") -> 0.00 | H14: =(G14*6%) -> 0 | I14: =G14+H14 -> 0 | K14: =J14-E14 -> 0 | L14: =IF(K14>0,K14*250.95,"0.00") -> 0.00 | M14: =(L14*6%) -> 0 | N14: =(L14+M14) -> 0 | P14: =O14-J14 -> 0 | Q14: =IF(P14>0,P14*248.06,"0.00") -> 0.00 | R14: =(Q14*6%) -> 0 | S14: =(Q14+R14) -> 0 | U14: =T14-O14 -> 0 | V14: =IF(U14>0,U14*358.9,"0.00") -> 0.00 | W14: =V14*6% -> 0 | X14: =V14+W14 -> 0 | Z14: =Y14-T14 -> 0 | AA14: =IF(Z14>0,Z14*296, "0.00") -> 0.00 | AB14: =AA14*6% -> 0 | AC14: =(AA14+AB14) -> 0 | AE14: =AD14-Y14 -> 0 | AF14: =IF(AE14>0,AE14*296, "0.00") -> 0.00 | AG14: =AF14*6% -> 0 | AH14: =(AF14+AG14) -> 0 | AJ14: =AI14-AD14 -> 0 | AK14: =IF(AJ14>0,AJ14*252.28, "0.00") -> 0.00 | AL14: =AK14*0.06 -> 0 | AM14: =(AK14+AL14) -> 0 | AO14: =(AN14-AI14) -> 0 | AP14: =IF(AO14>0,AO14*235.6, "0.00") -> 0.00 | AQ14: =(AP14*6%) -> 0 | AR14: =(AP14+AQ14) -> 0 | AT14: =(AS14-AN14) -> 0 | AU14: =IF(AT14>0,AT14*235.05, "0.00") -> 0.00 | AV14: =(AU14*6%) -> 0 | AW14: =(AU14+AV14) -> 0 | AZ14: =IF(AY14>0,AY14*229.55, "0.00") -> 0.00 | BA14: =(AZ14*6%) -> 0 | BB14: =(AZ14+BA14) -> 0 | BD14: =BC14-AX14 -> 0 | BE14: =IF(BD14>0,BD14*232,"0.00") -> 0.00 | BF14: =BE14*6% -> 0 | BG14: =BE14+BF14 -> 0 | BI14: =BH14-BC14 -> 0 | BJ14: =IF(BI14>0,BI14*231.8,"0.00") -> 0.00 | BK14: =BJ14*6% -> 0 | BL14: =BJ14+BK14 -> 0
A15: 6 | B15: 7A | D15: 29.98 | E15: 33.71 | F15: =E15-D15 -> 3.73 | G15: =IF(F15>0,F15*241.6,"0.00") -> 901.168 | H15: =(G15*6%) -> 54.07008 | I15: =G15+H15 -> 955.23808 | J15: 36.82 | K15: =J15-E15 -> 3.11 | L15: =IF(K15>0,K15*250.95,"0.00") -> 780.4545 | M15: =(L15*6%) -> 46.82727 | N15: =(L15+M15) -> 827.28177 | O15: 39.388 | P15: =O15-J15 -> 2.568 | Q15: =IF(P15>0,P15*248.06,"0.00") -> 637.01808 | R15: =(Q15*6%) -> 38.221085 | S15: =(Q15+R15) -> 675.23916 | T15: 42.045 | U15: =T15-O15 -> 2.657 | V15: =IF(U15>0,U15*358.9,"0.00") -> 953.5973 | W15: =V15*6% -> 57.215838 | X15: =V15+W15 -> 1010.8131 | Z15: =Y15-T15 -> -42.045 | AA15: =IF(Z15>0,Z15*296, "0.00") -> 0.00 | AB15: =AA15*6% -> 0 | AC15: =(AA15+AB15) -> 0 | AE15: =AD15-Y15 -> 0 | AF15: =IF(AE15>0,AE15*296, "0.00") -> 0.00 | AG15: =AF15*6% -> 0 | AH15: =(AF15+AG15) -> 0 | AJ15: =AI15-AD15 -> 0 | AK15: =IF(AJ15>0,AJ15*252.28, "0.00") -> 0.00 | AL15: =AK15*0.06 -> 0 | AM15: =(AK15+AL15) -> 0 | AO15: =(AN15-AI15) -> 0 | AP15: =IF(AO15>0,AO15*235.6, "0.00") -> 0.00 | AQ15: =(AP15*6%) -> 0 | AR15: =(AP15+AQ15) -> 0 | AT15: =(AS15-AN15) -> 0 | AU15: =IF(AT15>0,AT15*235.05, "0.00") -> 0.00 | AV15: =(AU15*6%) -> 0 | AW15: =(AU15+AV15) -> 0 | AX15: 20.95 | AZ15: =IF(AY15>0,AY15*229.55, "0.00") -> 0.00 | BA15: =(AZ15*6%) -> 0 | BB15: =(AZ15+BA15) -> 0 | BC15: 26.74 | BD15: =BC15-AX15 -> 5.79 | BE15: =IF(BD15>0,BD15*232,"0.00") -> 1343.28 | BF15: =BE15*6% -> 80.5968 | BG15: =BE15+BF15 -> 1423.8768 | BI15: =BH15-BC15 -> -26.74 | BJ15: =IF(BI15>0,BI15*231.8,"0.00") -> 0.00 | BK15: =BJ15*6% -> 0 | BL15: =BJ15+BK15 -> 0
A16: 7 | B16: 8A | D16: 30.97 | E16: 30.97 | G16: =IF(F16>0,F16*241.6,"0.00") -> 0.00 | H16: =(G16*6%) -> 0 | I16: =G16+H16 -> 0 | J16: 31.56 | K16: =J16-E16 -> 0.59 | L16: =IF(K16>0,K16*250.95,"0.00") -> 148.0605 | M16: =(L16*6%) -> 8.88363 | N16: =(L16+M16) -> 156.94413 | O16: 36.977 | P16: =O16-J16 -> 5.417 | Q16: =IF(P16>0,P16*248.06,"0.00") -> 1343.741 | R16: =(Q16*6%) -> 80.624461 | S16: =(Q16+R16) -> 1424.3655 | T16: 38.112 | U16: =T16-O16 -> 1.135 | V16: =IF(U16>0,U16*358.9,"0.00") -> 407.3515 | W16: =V16*6% -> 24.44109 | X16: =V16+W16 -> 431.79259 | Z16: =Y16-T16 -> -38.112 | AA16: =IF(Z16>0,Z16*296, "0.00") -> 0.00 | AB16: =AA16*6% -> 0 | AC16: =(AA16+AB16) -> 0 | AE16: =AD16-Y16 -> 0 | AF16: =IF(AE16>0,AE16*296, "0.00") -> 0.00 | AG16: =AF16*6% -> 0 | AH16: =(AF16+AG16) -> 0 | AJ16: =AI16-AD16 -> 0 | AK16: =IF(AJ16>0,AJ16*252.28, "0.00") -> 0.00 | AL16: =AK16*0.06 -> 0 | AM16: =(AK16+AL16) -> 0 | AO16: =(AN16-AI16) -> 0 | AP16: =IF(AO16>0,AO16*235.6, "0.00") -> 0.00 | AQ16: =(AP16*6%) -> 0 | AR16: =(AP16+AQ16) -> 0 | AT16: =(AS16-AN16) -> 0 | AU16: =IF(AT16>0,AT16*235.05, "0.00") -> 0.00 | AV16: =(AU16*6%) -> 0 | AW16: =(AU16+AV16) -> 0 | AX16: 23.27 | AZ16: =IF(AY16>0,AY16*229.55, "0.00") -> 0.00 | BA16: =(AZ16*6%) -> 0 | BB16: =(AZ16+BA16) -> 0 | BC16: 30.97 | BD16: =BC16-AX16 -> 7.7 | BE16: =IF(BD16>0,BD16*232,"0.00") -> 1786.4 | BF16: =BE16*6% -> 107.184 | BG16: =BE16+BF16 -> 1893.584 | BI16: =BH16-BC16 -> -30.97 | BJ16: =IF(BI16>0,BI16*231.8,"0.00") -> 0.00 | BK16: =BJ16*6% -> 0 | BL16: =BJ16+BK16 -> 0
B17: 1B | D17: 14.48 | E17: 15.33 | F17: =E17-D17 -> 0.85 | G17: =IF(F17>0,F17*241.6,"0.00") -> 205.36 | H17: =(G17*6%) -> 12.3216 | I17: =G17+H17 -> 217.6816 | J17: 15.98 | K17: =J17-E17 -> 0.65 | L17: =IF(K17>0,K17*250.95,"0.00") -> 163.1175 | M17: =(L17*6%) -> 9.78705 | N17: =(L17+M17) -> 172.90455 | O17: 16.029 | P17: =O17-J17 -> 0.049 | Q17: =IF(P17>0,P17*248.06,"0.00") -> 12.15494 | R17: =(Q17*6%) -> 0.7292964 | S17: =(Q17+R17) -> 12.884236 | T17: 16.483 | U17: =T17-O17 -> 0.454 | V17: =IF(U17>0,U17*358.9,"0.00") -> 162.9406 | W17: =V17*6% -> 9.776436 | X17: =V17+W17 -> 172.71704 | Z17: =Y17-T17 -> -16.483 | AA17: =IF(Z17>0,Z17*296, "0.00") -> 0.00 | AB17: =AA17*6% -> 0 | AC17: =(AA17+AB17) -> 0 | AE17: =AD17-Y17 -> 0 | AF17: =IF(AE17>0,AE17*296, "0.00") -> 0.00 | AG17: =AF17*6% -> 0 | AH17: =(AF17+AG17) -> 0 | AJ17: =AI17-AD17 -> 0 | AK17: =IF(AJ17>0,AJ17*252.28, "0.00") -> 0.00 | AL17: =AK17*0.06 -> 0 | AM17: =(AK17+AL17) -> 0 | AO17: =(AN17-AI17) -> 0 | AP17: =IF(AO17>0,AO17*235.6, "0.00") -> 0.00 | AQ17: =(AP17*6%) -> 0 | AR17: =(AP17+AQ17) -> 0 | AT17: =(AS17-AN17) -> 0 | AU17: =IF(AT17>0,AT17*235.05, "0.00") -> 0.00 | AV17: =(AU17*6%) -> 0 | AW17: =(AU17+AV17) -> 0 | AZ17: =IF(AY17>0,AY17*229.55, "0.00") -> 0.00 | BA17: =(AZ17*6%) -> 0 | BB17: =(AZ17+BA17) -> 0 | BC17: 13.85 | BE17: =IF(BD17>0,BD17*232,"0.00") -> 0.00 | BF17: =BE17*6% -> 0 | BG17: =BE17+BF17 -> 0 | BI17: =BH17-BC17 -> -13.85 | BJ17: =IF(BI17>0,BI17*231.8,"0.00") -> 0.00 | BK17: =BJ17*6% -> 0 | BL17: =BJ17+BK17 -> 0
A18: 9 | B18: 2B | D18: 24.65 | E18: 30.92 | F18: =E18-D18 -> 6.27 | G18: =IF(F18>0,F18*241.6,"0.00") -> 1514.832 | H18: =(G18*6%) -> 90.88992 | I18: =G18+H18 -> 1605.7219 | J18: 38.24 | K18: =J18-E18 -> 7.32 | L18: =IF(K18>0,K18*250.95,"0.00") -> 1836.954 | M18: =(L18*6%) -> 110.21724 | N18: =(L18+M18) -> 1947.1712 | O18: 44.878 | P18: =O18-J18 -> 6.638 | Q18: =IF(P18>0,P18*248.06,"0.00") -> 1646.6223 | R18: =(Q18*6%) -> 98.797337 | S18: =(Q18+R18) -> 1745.4196 | T18: 50.681 | U18: =T18-O18 -> 5.803 | V18: =IF(U18>0,U18*358.9,"0.00") -> 2082.6967 | W18: =V18*6% -> 124.9618 | X18: =V18+W18 -> 2207.6585 | Z18: =Y18-T18 -> -50.681 | AA18: =IF(Z18>0,Z18*296, "0.00") -> 0.00 | AB18: =AA18*6% -> 0 | AC18: =(AA18+AB18) -> 0 | AE18: =AD18-Y18 -> 0 | AF18: =IF(AE18>0,AE18*296, "0.00") -> 0.00 | AG18: =AF18*6% -> 0 | AH18: =(AF18+AG18) -> 0 | AJ18: =AI18-AD18 -> 0 | AK18: =IF(AJ18>0,AJ18*252.28, "0.00") -> 0.00 | AL18: =AK18*0.06 -> 0 | AM18: =(AK18+AL18) -> 0 | AO18: =(AN18-AI18) -> 0 | AP18: =IF(AO18>0,AO18*235.6, "0.00") -> 0.00 | AQ18: =(AP18*6%) -> 0 | AR18: =(AP18+AQ18) -> 0 | AT18: =(AS18-AN18) -> 0 | AU18: =IF(AT18>0,AT18*235.05, "0.00") -> 0.00 | AV18: =(AU18*6%) -> 0 | AW18: =(AU18+AV18) -> 0 | AZ18: =IF(AY18>0,AY18*229.55, "0.00") -> 0.00 | BA18: =(AZ18*6%) -> 0 | BB18: =(AZ18+BA18) -> 0 | BC18: 20.4 | BE18: =IF(BD18>0,BD18*232,"0.00") -> 0.00 | BF18: =BE18*6% -> 0 | BG18: =BE18+BF18 -> 0 | BI18: =BH18-BC18 -> -20.4 | BJ18: =IF(BI18>0,BI18*231.8,"0.00") -> 0.00 | BK18: =BJ18*6% -> 0 | BL18: =BJ18+BK18 -> 0
A19: USES PER MONTH | F19: =SUM(F10:F18) -> 25.463 | G19: =SUM(G10:G18) -> 6151.8608 | H19: =SUM(H10:H18) -> 369.11165 | I19: =SUM(I10:I18) -> 6520.9724 | K19: =SUM(K10:K18) -> 31.362 | L19: =SUM(L10:L18) -> 7870.2939 | M19: =SUM(M10:M18) -> 472.21763 | N19: =SUM(N10:N18) -> 8342.5115 | P19: =SUM(P10:P18) -> 32.086 | Q19: =SUM(Q10:Q18) -> 7959.2532 | R19: =SUM(R10:R18) -> 477.55519 | S19: =SUM(S10:S18) -> 8436.8083 | U19: =SUM(U10:U18) -> 14.529 | V19: =SUM(V10:V18) -> 8734.9082 | W19: =SUM(W10:W18) -> 524.09449 | X19: =SUM(X10:X18) -> 9259.0027 | Z19: =SUM(Z10:Z18) -> -370.947 | AA19: =SUM(AA10:AA18) -> 0 | AB19: =SUM(AB10:AB18) -> 0 | AC19: =SUM(AC10:AC18) -> 0 | AE19: =SUM(AE10:AE18) -> 0 | AF19: =SUM(AF10:AF18) -> 0 | AG19: =SUM(AG10:AG18) -> 0 | AH19: =SUM(AH10:AH18) -> 0 | AJ19: =SUM(AJ10:AJ18) -> 0 | AK19: =SUM(AK10:AK18) -> 0 | AL19: =SUM(AL10:AL18) -> 0 | AM19: =SUM(AM10:AM18) -> 0 | AO19: =SUM(AO10:AO18) -> 0 | AP19: =SUM(AP10:AP18) -> 0 | AQ19: =SUM(AQ10:AQ18) -> 0 | AR19: =SUM(AR10:AR18) -> 0 | AU19: =SUM(AU10:AU18) -> 0 | AV19: =SUM(AV10:AV18) -> 0 | AW19: =SUM(AW10:AW18) -> 0 | AY19: =SUM(AY10:AY18) -> 0 | AZ19: =SUM(AZ10:AZ18) -> 0 | BA19: =SUM(BA10:BA18) -> 0 | BB19: =SUM(BB10:BB18) -> 0 | BD19: =SUM(BD10:BD18) -> 44.31 | BE19: =SUM(BE10:BE18) -> 10279.92 | BF19: =SUM(BF10:BF18) -> 616.7952 | BG19: =SUM(BG10:BG18) -> 10896.715 | BJ19: =SUM(BJ10:BJ18) -> 0 | BK19: =SUM(BK10:BK18) -> 0 | BL19: =SUM(BL10:BL18) -> 0
I22: =I19 -> 6520.9724 | N22: =N19 -> 8342.5115 | BG22: 10896
I23: 5 | N23: 5 | BG23: 5
I24: =I22/I23 -> 1304.1945 | N24: =N22/N23 -> 1668.5023 | BG24: =BG22/BG23 -> 2179.2

Sheet PAYMENT RECORD
A1: URBAN GAZ @ KHILKHET
A3: PAYMENT RECORD - SURZO DREAM HOUSE
B6: FLAT DETAILS | E6: JANUARY - 2025 | G6: FEBRUARY - 2025 | I6: MARCH - 2025 | K6: APRIL - 2025 | M6: MAY - 2025 | O6: JUNE - 2025 | Q6: JULY - 2025 | S6: AUGUST - 2025 | U6: SEPTEMBER - 2025 | W6: OCTOBER - 2025 | Y6: NOVEMBER - 2025 | AA6: DECEMBER - 2025 | AC6: JULY - 2025 | AE6: AUGUST - 2025 | AG6: SEPTEMBER - 2025 | AI6: OCTOBER - 2025 | AK6: NOVEMBER - 2025 | AM6: DECEMBER - 2025
B7: FLAT NUMBER | C7: NAME | D7: CONTACT | E7: BILL [BDT] | F7: PAYMENT | G7: BILL [BDT] | H7: PAYMENT | I7: BILL [BDT] | J7: PAYMENT | K7: BILL [BDT] | L7: PAYMENT | M7: BILL [BDT] | N7: PAYMENT | O7: BILL [BDT] | P7: PAYMENT | Q7: BILL [BDT] | R7: PAYMENT | S7: BILL [BDT] | T7: PAYMENT | U7: BILL [BDT] | V7: PAYMENT | W7: BILL [BDT] | X7: PAYMENT | Y7: BILL [BDT] | Z7: PAYMENT | AA7: BILL [BDT] | AB7: PAYMENT | AC7: BILL [BDT] | AD7: PAYMENT | AE7: BILL [BDT] | AF7: PAYMENT | AG7: BILL [BDT] | AH7: PAYMENT | AI7: BILL [BDT] | AJ7: PAYMENT | AK7: BILL [BDT] | AL7: PAYMENT | AM7: BILL [BDT] | AN7: PAYMENT
A8: 1 | B8: 3A | C8: ='CUSTOMER DETAILS'!H9 -> AMRAN HOSSAIN | D8: ='CUSTOMER DETAILS'!J9 -> (+880)1792735556 | E8: ='R, C & BILL'!I10 -> 0 | G8: ='R, C & BILL'!N10 -> 1311.4145 | I8: ='R, C & BILL'!S10 -> 590.30838 | K8: ='R, C & BILL'!X10 -> 0 | M8: ='R, C & BILL'!AC10 -> 0 | O8: ='R, C & BILL'!AM10 -> 0 | AA8: ='R, C & BILL'!BL10 -> 0 | AC8: ='R, C & BILL'!AR10 -> 0 | AE8: ='R, C & BILL'!AR10 -> 0 | AG8: ='R, C & BILL'!AW10 -> 0 | AI8: ='R, C & BILL'!BB10 -> 0 | AK8: ='R, C & BILL'!AU10 -> 0.00 | AM8: ='R, C & BILL'!BL10 -> 0
A9: 2 | B9: 5A | E9: ='R, C & BILL'!I11 -> 2786.3245 | F9: UNPAID | G9: ='R, C & BILL'!N11 -> 2979.2784 | I9: ='R, C & BILL'!S11 -> 2129.8432 | K9: ='R, C & BILL'!X11 -> 4393.2518 | M9: ='R, C & BILL'!AC11 -> 0 | O9: ='R, C & BILL'!AM11 -> 0 | Q9: ='R, C & BILL'!AM11 -> 0 | S9: ='R, C & BILL'!AR11 -> 0 | U9: ='R, C & BILL'!AW11 -> 0 | W9: ='R, C & BILL'!BB11 -> 0 | Y9: ='R, C & BILL'!BG11 -> 5299.576 | AA9: ='R, C & BILL'!BL11 -> 0 | AC9: ='R, C & BILL'!AR11 -> 0 | AE9: ='R, C & BILL'!AR11 -> 0 | AG9: ='R, C & BILL'!AW11 -> 0 | AI9: ='R, C & BILL'!BB11 -> 0 | AK9: ='R, C & BILL'!AU11 -> 0.00 | AM9: ='R, C & BILL'!BL11 -> 0
A10: 3 | B10: 6A | E10: ='R, C & BILL'!I12 -> 956.00637 | F10: UNPAID | G10: ='R, C & BILL'!N12 -> 783.92263 | I10: ='R, C & BILL'!S12 -> 1361.259 | K10: ='R, C & BILL'!X12 -> 1042.7696 | M10: ='R, C & BILL'!AC12 -> 0 | O10: ='R, C & BILL'!AM12 -> 0 | Q10: ='R, C & BILL'!AM12 -> 0 | S10: ='R, C & BILL'!AR12 -> 0 | U10: ='R, C & BILL'!AW12 -> 0 | W10: ='R, C & BILL'!BB12 -> 0 | Y10: ='R, C & BILL'!BG12 -> 1650.1232 | AA10: ='R, C & BILL'!BL12 -> 0 | AC10: ='R, C & BILL'!AR12 -> 0 | AE10: ='R, C & BILL'!AR12 -> 0 | AG10: ='R, C & BILL'!AW12 -> 0 | AI10: ='R, C & BILL'!BB12 -> 0 | AK10: ='R, C & BILL'!AU12 -> 0.00 | AM10: ='R, C & BILL'!BL12 -> 0
A11: 4 | B11: 1B | E11: ='R, C & BILL'!I13 -> 0 | G11: ='R, C & BILL'!N13 -> 163.5943 | I11: ='R, C & BILL'!S13 -> 497.48929 | K11: ='R, C & BILL'!X13 -> 0 | M11: ='R, C & BILL'!AC13 -> 0 | O11: ='R, C & BILL'!AM13 -> 0 | Q11: ='R, C & BILL'!AM13 -> 0 | S11: ='R, C & BILL'!AR13 -> 0 | U11: ='R, C & BILL'!AW13 -> 0 | W11: ='R, C & BILL'!BB13 -> 0 | Y11: ='R, C & BILL'!BG13 -> 0 | AA11: ='R, C & BILL'!BL13 -> 0 | AC11: ='R, C & BILL'!AR13 -> 0 | AE11: ='R, C & BILL'!AR13 -> 0 | AG11: ='R, C & BILL'!AW13 -> 0 | AI11: ='R, C & BILL'!BB13 -> 0 | AK11: ='R, C & BILL'!AU13 -> 0.00 | AM11: ='R, C & BILL'!BL13 -> 0
A12: 5 | B12: 2B | E12: ='R, C & BILL'!I14 -> 0 | G12: ='R, C & BILL'!N14 -> 0 | I12: ='R, C & BILL'!S14 -> 0 | K12: ='R, C & BILL'!X14 -> 0 | M12: ='R, C & BILL'!AC14 -> 0 | O12: ='R, C & BILL'!AM14 -> 0 | Q12: ='R, C & BILL'!AM14 -> 0 | S12: ='R, C & BILL'!AR14 -> 0 | U12: ='R, C & BILL'!AW14 -> 0 | W12: ='R, C & BILL'!BB14 -> 0 | Y12: ='R, C & BILL'!BG14 -> 0 | AA12: ='R, C & BILL'!BL14 -> 0 | AC12: ='R, C & BILL'!AR14 -> 0 | AE12: ='R, C & BILL'!AR14 -> 0 | AG12: ='R, C & BILL'!AW14 -> 0 | AI12: ='R, C & BILL'!BB14 -> 0 | AK12: ='R, C & BILL'!AU14 -> 0.00 | AM12: ='R, C & BILL'!BL14 -> 0
A13: 6 | B13: 3B | E13: ='R, C & BILL'!I15 -> 955.23808 | F13: UNPAID | G13: ='R, C & BILL'!N15 -> 827.28177 | I13: ='R, C & BILL'!S15 -> 675.23916 | K13: ='R, C & BILL'!X15 -> 1010.8131 | M13: ='R, C & BILL'!AC15 -> 0 | O13: ='R, C & BILL'!AM15 -> 0 | Q13: ='R, C & BILL'!AM15 -> 0 | S13: ='R, C & BILL'!AR15 -> 0 | U13: ='R, C & BILL'!AW15 -> 0 | W13: ='R, C & BILL'!BB15 -> 0 | Y13: ='R, C & BILL'!BG15 -> 1423.8768 | AA13: ='R, C & BILL'!BL15 -> 0 | AC13: ='R, C & BILL'!AR15 -> 0 | AE13: ='R, C & BILL'!AR15 -> 0 | AG13: ='R, C & BILL'!AW15 -> 0 | AI13: ='R, C & BILL'!BB15 -> 0 | AK13: ='R, C & BILL'!AU15 -> 0.00 | AM13: ='R, C & BILL'!BL15 -> 0
A14: 7 | B14: 4B | E14: ='R, C & BILL'!I16 -> 0 | G14: ='R, C & BILL'!N16 -> 156.94413 | I14: ='R, C & BILL'!S16 -> 1424.3655 | K14: ='R, C & BILL'!X16 -> 431.79259 | M14: ='R, C & BILL'!AC16 -> 0 | O14: ='R, C & BILL'!AM16 -> 0 | Q14: ='R, C & BILL'!AM16 -> 0 | S14: ='R, C & BILL'!AR16 -> 0 | U14: ='R, C & BILL'!AW16 -> 0 | W14: ='R, C & BILL'!BB16 -> 0 | Y14: ='R, C & BILL'!BG16 -> 1893.584 | AA14: ='R, C & BILL'!BL16 -> 0 | AC14: ='R, C & BILL'!AR16 -> 0 | AE14: ='R, C & BILL'!AR16 -> 0 | AG14: ='R, C & BILL'!AW16 -> 0 | AI14: ='R, C & BILL'!BB16 -> 0 | AK14: ='R, C & BILL'!AU16 -> 0.00 | AM14: ='R, C & BILL'!BL16 -> 0
A15: 8 | B15: 7B | E15: ='R, C & BILL'!I17 -> 217.6816 | F15: UNPAID | G15: ='R, C & BILL'!N17 -> 172.90455 | I15: ='R, C & BILL'!S17 -> 12.884236 | K15: ='R, C & BILL'!X17 -> 172.71704 | M15: ='R, C & BILL'!AC17 -> 0 | O15: ='R, C & BILL'!AM17 -> 0 | AC15: ='R, C & BILL'!AR17 -> 0 | AE15: ='R, C & BILL'!AR17 -> 0 | AG15: ='R, C & BILL'!AW17 -> 0 | AI15: ='R, C & BILL'!BB17 -> 0 | AK15: ='R, C & BILL'!AU17 -> 0.00 | AM15: ='R, C & BILL'!BL17 -> 0
A16: 9 | B16: 2C | E16: ='R, C & BILL'!I18 -> 1605.7219 | F16: UNPAID | G16: ='R, C & BILL'!N18 -> 1947.1712 | I16: ='R, C & BILL'!S18 -> 1745.4196 | K16: ='R, C & BILL'!X18 -> 2207.6585 | M16: ='R, C & BILL'!AC18 -> 0 | O16: ='R, C & BILL'!AM18 -> 0 | AC16: ='R, C & BILL'!AR18 -> 0 | AE16: ='R, C & BILL'!AR18 -> 0 | AG16: ='R, C & BILL'!AW18 -> 0 | AI16: ='R, C & BILL'!BB18 -> 0 | AK16: ='R, C & BILL'!AU18 -> 0.00 | AM16: ='R, C & BILL'!BL18 -> 0
A17: USES PER MONTH | E17: =SUM(E9:E16) -> 6520.9724 | G17: =SUM(G9:G16) -> 7031.097 | I17: =SUM(I8:I16) -> 8436.8083 | K17: =SUM(K8:K16) -> 9259.0027 | M17: =SUM(M9:M16) -> 0 | O17: =SUM(O9:O16) -> 0 | Q17: =SUM(Q9:Q16) -> 0 | S17: =SUM(S9:S16) -> 0 | U17: =SUM(U9:U16) -> 0 | W17: =SUM(W8:W16) -> 0 | Y17: =SUM(Y8:Y16) -> 10267.16 | AA17: =SUM(AA9:AA16) -> 0 | AC17: =SUM(AC8:AC16) -> 0 | AE17: =SUM(AE8:AE16) -> 0 | AG17: =SUM(AG8:AG16) -> 0 | AI17: =SUM(AI8:AI16) -> 0 | AK17: =SUM(AK8:AK16) -> 0 | AM17: =SUM(AM8:AM16) -> 0

Sheet CUSTOMER DETAILS
A1: URBAN GAZ @ KHILKHET
A3: PAYMENT RECORD - SURZO DREAM HOUSE
A6: SL NO | B6: FLAT NUMBER | C6: OWNER | H6: TENANT | M6: REMARKS
C7: CUSTOMER DETAILS | E7: CONTACT | H7: CUSTOMER DETAILS | J7: CONTACT
C8: NAME | D8: NATIONAL ID NO | E8: CELL NO | F8: EMAIL | G8: PARMANENT ADDRESS | H8: NAME | I8: NATIONAL ID NO | J8: CELL NO | K8: EMAIL | L8: PARMANENT ADDRESS
A9: 1 | B9: 1A | C9: EHSANUL KARIM SUNNY | D9: [19902699038000063] | E9: (+880)1672 593504 | F9: midu49bun@gmail.com | G9: HOUSE # 184, ROAD # 05, BLOCK # D, BASHUNDHARA RESIDENTIAL AREA | H9: AMRAN HOSSAIN | I9: 3755459644 | J9: (+880)1792735556 | K9: EMAIL2ARMAN@GMAIL.COM | L9: H#184; JAMIRA LATA; BJOLA SADAR; BHOLA | M9: CASH PAYMENT
A10: 2 | B10: 2A
A11: 3 | B11: 3A
A12: 4 | B12: 4A
A13: 5 | B13: 5A
A14: 6 | B14: 6A
A15: 7 | B15: 7A
A16: 8 | B16: 8A
A17: 9 | B17: 9A
A18: 10 | B18: 1B
A19: 11 | B19: 2B
A20: 12 | B20: 3B
A21: 13 | B21: 4B
... A36: 28 | B36: GF
